<mujoco model="double_inverted_pendulum">

    <option gravity="0 0 -9.81" timestep="0.002" integrator="RK4"/>

    <worldbody>

        <body name="base" pos="0 0 1">
            <joint name="theta1" type="hinge" axis="0 1 0" damping="0.01"/>
            <geom type="capsule" fromto="0 0 0 0 0 0.5" size="0.03" mass="1"/>

            <body name="link2" pos="0 0 0.5">
                <joint name="theta2" type="hinge" axis="0 1 0" damping="0.01"/>
                <geom type="capsule" fromto="0 0 0 0 0 0.5" size="0.03" mass="1"/>
            </body>

        </body>

    </worldbody>

</mujoco>